Workbook

Sheet Store Metrics
A1: Key 1 | B1: Key 2 | C1: Key 3 | D1: Key4 | E1: Metric Name | F1: Metric Value Types | G1: Notes | H1: Will be used in Outlier Model?
A2: Store | E2: Returned Items | F2: Count and Amount | H2: Yes
A3: Store | E3: Voided Items | F3: Count and Amount | H3: Yes
A4: Store | E4: Stored Transactions | F4: Count and Amount | H4: Yes
A5: Store | E5: Stored not recalled Transactions | F5: Count and Amount | H5: Yes
A6: Store | E6: Transaction Cancel | F6: Count and Amount | G6: Need to be able to distinguish between manually cancelled vs. stored not recalled that are often auto cancelled by the POS | H6: Yes
A7: Store | E7: Department Key Entries – Sales | F7: Count and Amount | H7: Yes
A8: Store | E8: Item Key Entries – Sales | F8: Count and Amount | H8: Yes
A9: Store | E9: Department Key Entries – Returns | F9: Count and Amount | H9: Yes
A10: Store | E10: Item Key Entries – Returns | F10: Count and Amount | H10: Yes
A11: Store | E11: Not on File | F11: Count | G11: Remove | H11: No, because I don't know what this means
A12: Store | E12: Age Information Check | F12: Count | H12: Yes
A13: Store | E13: Voided Tenders | F13: Count and Amount | H13: Yes
A14: Store | E14: Manual Price Override | F14: Count and Amount | H14: Yes
A15: Store | E15: Manual Discount Applied | F15: Count and Amount | H15: Yes
A16: Store | E16: Manual Tax Exempt | F16: Count and Amount | H16: Yes
A17: Store | E17: Tax Modified | F17: Count and Amount | H17: Yes
A18: Store | E18: Zero Value Transactions | F18: Count | H18: Yes
A19: Store | E19: Key entered Payment Card | F19: Count and Amount | H19: Yes
A20: Store | E20: Key entered Loyalty Card | F20: Count and Points | H20: Yes
A21: Store | E21: Key entered Gift Card | F21: Count and Amount | H21: Yes
A22: Store | E22: Key entered Staff Discount Card | F22: Count and Amount | H22: Yes
A23: Store | E23: Post Void | F23: Count and Amount | H23: Yes
A24: Store | E24: Loyalty Points Added at Till | F24: Count and Points | H24: Yes
A25: Store | E25: Drive Offs | F25: Count and Amount | G25: Rarely Populated | H25: If we have it, however not sure what the store can do about it
A26: Store | E26: No Sale | F26: Count and Amount | H26: Yes
A27: Store | E27: Price Checks | F27: Count | H27: Yes
A28: Store | E28: Zero priced Items | F28: Count | H28: Yes
A29: Store | E29: Automatic Discounts Applied | F29: Count and Amount | H29: Yes
A30: Store | E30: Positive Discount Resulting in Price Increase | F30: Count and Amount | H30: Yes
A31: Store | E31: Items Per Minute | F31: Count | G31: Over what time period? | H31: Yes
A32: Store | E32: Average Basket Size | F32: Amount | H32: Yes
A33: Store | E33: Overs | F33: Count | G33: R1 - When we haver an O/S solution | H33: If we have it
A34: Store | E34: Shorts | F34: Count | G34: R1 - When we haver an O/S solution | H34: If we have it
A35: Store | E35: Coupon | F35: Count and Amount | H35: Yes
A36: Store | E36: Sold Items | F36: Count and Amount | G36: This does not exist at the moment | H36: Yes
A37: Store | E37: All Transactions | F37: Count | G37: New
A38: Store | E38: Customer Present Transactions | F38: Count and Amount | G38: New - All Transactions excluding no sale, control transactions
A39: Store | E39: Mean Item Selling Price | F39: Amount | G39: New
A40: Store | E40: Store Coupons | F40: Count and Amount | G40: New
...

Sheet Outlier Metrics
A1: Metric Name | B1: Source Field (from model output results)
A2: Overall Outlier Score
A3: =_xlfn.CONCAT("Outlier Score for ", 'Store Metrics'!E2) -> Outlier Score for Returned Items
A4: =_xlfn.CONCAT("Outlier Score for ", 'Store Metrics'!E3) -> Outlier Score for Voided Items
A5: =_xlfn.CONCAT("Outlier Score for ", 'Store Metrics'!E4) -> Outlier Score for Stored Transactions
A6: =_xlfn.CONCAT("Outlier Score for ", 'Store Metrics'!E5) -> Outlier Score for Stored not recalled Transactions
A7: =_xlfn.CONCAT("Outlier Score for ", 'Store Metrics'!E6) -> Outlier Score for Transaction Cancel
A8: =_xlfn.CONCAT("Outlier Score for ", 'Store Metrics'!E7) -> Outlier Score for Department Key Entries – Sales
A9: =_xlfn.CONCAT("Outlier Score for ", 'Store Metrics'!E8) -> Outlier Score for Item Key Entries – Sales
A10: =_xlfn.CONCAT("Outlier Score for ", 'Store Metrics'!E9) -> Outlier Score for Department Key Entries – Returns
A11: =_xlfn.CONCAT("Outlier Score for ", 'Store Metrics'!E10) -> Outlier Score for Item Key Entries – Returns
A12: =_xlfn.CONCAT("Outlier Score for ", 'Store Metrics'!E11) -> Outlier Score for Not on File
A13: =_xlfn.CONCAT("Outlier Score for ", 'Store Metrics'!E12) -> Outlier Score for Age Information Check
A14: =_xlfn.CONCAT("Outlier Score for ", 'Store Metrics'!E13) -> Outlier Score for Voided Tenders
... A36: =_xlfn.CONCAT("Outlier Score for ", 'Store Metrics'!E35) -> Outlier Score for Coupon

Sheet Similar Stores
A1: Key 1 | B1: Key 2 | C1: Key 3 | D1: Key4 | E1: Name | F1: Metric / Attribute | G1: Notes
A2: Store | E2: All Transactions | F2: Count and Amount
A3: Store | E3: Location Type | F3: Attribute
A4: Store | E4: Sell Area Size | F4: Attribute
A5: Store | E5: Sold Itmes | F5: Count and Amount
A6: Store | E6: Open Date | F6: Attribute
A7: Store | E7: Last Remodel Date | F7: Attribute
A8: Store | E8: Currency Code | F8: Attribute
A9: Store | E9: Average Basket Size | F9: Count
A10: Store | E10: Return Rate % | F10: % to Sales
A11: Store | E11: POS Type | F11: Attribute
A12: Store | B12: TenderType | E12: Tender Type % | F12: % of Sales by Tender
A13: Store | B13: DiscountType | E13: Staff Dsicount % | F13: % to Sales
A14: Store | E14: Distinct Cashiers | F14: Count of Cashiers
A15: Store | E15: Store Manager Tenure | F15: Value
A16: Store | B16: EmployeeType | E16: Part Time% | F16: % of Part Time Operators

Sheet R1 Metric logic review
A1: Key 1 | B1: Key 2 | C1: Key 3 | D1: Key4 | E1: Metric Name | F1: Metric Value Types | G1: Metrics in the Box So far | H1: SRA? | I1: Reason Codes | J1: Notes | K1: Benefit Category | L1: Summary Fields | M1: Conditional Logic | N1: Aggregate Fields | O1: Notes on Logic
A2: Store | E2: Returned Items | F2: Count and Amount | G2: Store - ReturnedItems - Count and Amount | H2: SRA | I2: Damaged, Faulty, Unwanted, Recall, Exchange… | J2: Need to list all that are required | K2: Shrink | L2: StoreNo | M2: Training Mode is false and Void Ticket Flag is false and Total Return Count is greater than 0 | N2: Sum Fast Fact Total Return Count, Sum Total Return Amount | O2: Missing No Sale Flag
A3: Store | B3: Reason Code | E3: Returned Items | F3: Count and Amount | G3: Store - ReturnType - Returned Items By StoreReason - Count and Amount | I3: As Above | L3: Store No, Item Return Type | M3: TrainingModeFlg is False, Void Ticket Flag is false, and Fast Fact Total Return Count is greater than 0 and Item Return Type is greather than 0 | N3: Sum Item Number of Items, Sum Item Amount Charged | O3: Missing No Sale Flag and Item Was Canceled is false
A4: Store | E4: Voided Items | F4: Count and Amount | G4: VoidedItemsByStore | H4: SRA | K4: Shrink | L4: Store No | M4: Training Mode is false and Void Ticket Flag is false and Was Canceled is true | N4: Sum Item Number of Items, Sum Item Amount Charged | O4: Missing No Sale Flag and Item Was Canceled is false
A5: Store | E5: Stored Transactions | F5: Count and Amount | G5: Store - Stored Transactions - Count and Amount | K5: Shrink | L5: Store No | M5: Training Mode is false and Void Ticket Flag is false and Stored Flag is True | N5: Count of Header Transaction Id, Sum of Ticket Amount | O5: Missing No Sale Flag, Need to Check ARDM Mapping
A6: Store | E6: Stored not recalled Transactions | F6: Count and Amount | G6: Store - Stored Not Recalled Transactions - Count and Amount | H6: SRA - This is typically a component of Transaction Cancels because an resumed suspend is often auto cancelled at the day close on the register. If it can be identified specifically it is good to have it as a separate metric. | K6: Shrink | L6: Store No | M6: Training Mode is false and Void Ticket is false and Recalled Flag is True | N6: Count of Header Transaction Id, Sum of Ticket Amount | O6: Missing No Sale Flag, Need to Check ARDM Mapping
A7: Store | E7: Transaction Cancel | F7: Count and Amount | H7: SRA | O7: Missing No Sale Flag
A8: Store | E8: Department Key Entries – Sales | F8: Count and Amount | G8: Store - DepartmentKeyEntries–Sales - Count and Amount | K8: Shrink | L8: Store No | M8: Training Mode is false and Void Ticket is false and Item Retun Type is 0 and Entry Mode is 2 and Item Dept Waste is 2 | N8: Sum Item Number of Items, Sum Item Amount Charged | O8: Missing No Sale Flag and Item Was Canceled
A9: Store | E9: Item Key Entries – Sales | F9: Count and Amount | G9: Store - ItemKeyEntries–Sales - Count and Amount | K9: Shrink | L9: Store No | M9: Training Mode is false and Void Ticket is false and Item Retun Type is 0 and Entry Mode is 2 and Item Dept Waste is 1 | N9: Sum Item Number of Items, Sum Item Amount Charged | O9: Missing No Sale Flag and Item Was Canceled
A10: Store | E10: Department Key Entries – Returns | F10: Count and Amount | K10: Shrink | L10: Store No | M10: Training Mode is false and Void Ticket is false and Item Return Type is 0 and Entry Mode is 2 and Item Dept Waste is 2 | N10: Sum Item Number of Items, Sum Item Amount Charged | O10: Missing No Sale Flag and Item Was Canceled
A11: Store | E11: Item Key Entries – Returns | F11: Count and Amount | G11: Store - ItemKeyEntries–Returns - Count and Amount | K11: Shrink | L11: Store No | M11: Training Mode is false and Void Ticket is false and Item Return Type is 0 and Entry Mode is 2 and Item Dept Waste is 1 | N11: Sum Item Number of Items, Sum Item Amount Charged | O11: Missing No Sale Flag and Item Was Canceled
A12: Store | E12: Not on File | F12: Count | G12: Store - NotOnFile - Count | K12: Productivity | L12: Store No | M12: Training Mode is false and Void Ticket is false | N12: Count of Not on File Transaction Id | O12: Missing No Sale Flag and Training Mode is false and Void Ticket is false
A13: Store | E13: Age Information Check | F13: Count | G13: Store - AgeInformationCheck - Count | K13: Shrink | L13: Store No | M13: Training Mode is false and Void Ticket is false | N13: Count of Age Information Transaction Id | O13: Missing No Sale Flag
A14: Store | E14: Voided Tenders | F14: Count and Amount | G14: Store - VoidedTenders - Count and Amount | K14: Shrink | L14: Store No | M14: Training Mode is false and Void Ticket is false and Tender WasVoidFlg is true | N14: Count of Tender Transaction Id, Sum Tender Amount | O14: Missing No Sale Flag
A15: Store | E15: Manual Price Override | F15: Count and Amount | G15: Store - ManualPriceOverride - Count and Amount | K15: Shrink, Revenue | L15: Store No | M15: Training Mode is false and Void Ticket is false Manual Price Flg is true and Item Discount Value Change Method is 2 | N15: Count of Item Discount Transaction Id, Sum Actual Price | O15: Missing No Sale Flag and Item Was Canceled
A16: Store | E16: Manual Discount Applied | F16: Count and Amount | G16: Store - ManualDiscountApplied - Count and Amount | K16: Shrink, Revenue | L16: Store No | M16: Manual Price Flg is true and Value Change Method is 2 | N16: Sum Item Quantity, Sum Item Discount Amount | O16: Missing No Sale Flag and Training Mode is false and Void Ticket is false
A17: Store | B17: Reason Code | E17: Operator Action | F17: Count | G17: Store - Reason - OperatorAction - Count | I17: Sign In, Sign Off, Sub Total, Secure Mode… | J17: Need to list all that are required | K17: Shrink, Productivity | L17: Store No, Operator Action Action Type | M17: Training Mode is false and Void Ticket is false | N17: Count of Operator Action Transaction Id | O17: Missing No Sale Flag
A18: Store | E18: Manual Tax Exempt | F18: Count and Amount | G18: Store - ManualTaxExempt - Count and Amount | K18: Shrink, Revenue | L18: Store No | M18: Training Mode is false and Void Ticket is false and Item Tax Exempt is true | N18: Count of Item Transaction Id and Sum Item Amount Charged | O18: Missing No Sale Flag
A19: Store | E19: Tax Modified | F19: Count and Amount | G19: Store - TaxModified - Count and Amount | H19: SRA - But rarely available in the Tlog data | K19: Shrink, Revenue | L19: Store No | M19: Item Tax Override Flag is true | N19: Sum Item Number of Items, Sum Item Amount Charged | O19: Missing No Sale Flag and Training Mode is false and Void Ticket is false and Item Was Canceled
A20: Store | E20: Zero Value Transactions | F20: Count | G20: Store - Zero ValueTransactions - Count | K20: Shrink | L20: Store No | M20: Training Flag is false and Ticket Amount is 0 | N20: Count of Transaction Id | O20: Missing No Sale Flag and Void Ticket Flag is false, and Number Line Item greater than 0
A21: Store | E21: Key entered Payment Card | F21: Count and Amount | G21: Store - KeyEnteredPaymentCard - Count and Amount | K21: Shrink | L21: Store No | M21: Training Flag is false and Void Ticket is false and Fast Fact Hand Keyed Payment Card Count is greater than 0 and Tender Entry Mode 2 | N21: Sum Fast Fact Hand Keyed Payment Card Count and Sum Tender Amount | O21: Missing No Sale Flag
A22: Store | E22: Key entered Loyalty Card | F22: Count and Points | G22: Store - KeyEnteredLoyaltyCard - Count and Amount | K22: Shrink | L22: Store No | M22: Training Flag is False and Void Ticket is false Loyalty Card Entry Mode is 2 | N22: Count of Transaction Id and Sum of Loyalty Card Points | O22: Missing No Sale Flag
A23: Store | E23: Key entered Gift Card | F23: Count and Amount | G23: Store - KeyEnteredGiftCard - Count and Amount | K23: Shrink | L23: Store No | M23: Training Flag is false and Void Ticket is false and Gift Card Entry Mode is 2 | N23: Count of Transaction Id and Sum of Gift Card Approval Amount | O23: Missing No Sale Flag
A24: Store | E24: Key entered Staff Discount Card | F24: Count and Amount | G24: Store - KeyEnteredStaffDiscountCard - Count and Amount | K24: Shrink | L24: Store No | M24: Training Flag is false and Void Ticket is false Staff Discount Entry Mode is 2 | N24: Count of Transaction Id and Sum Tender Amount | O24: Missing No Sale Flag
A25: Store | E25: Post Void | F25: Count and Amount | G25: Store - PostVoid - Count and Amount | H25: SRA | K25: Shrink | L25: Store No | M25: Training Flag is false and Void Ticket is false | N25: Count of Fast Fact Total Line count and Total Line Amount | O25: Missing No Sale Flag, Void After Flag is True, Count of Header Transaction Id
A26: Store | E26: Loyalty Points Added at Till | F26: Count and Points | G26: Store - LoyaltyPointsAddedAtTill - Count and Amount | K26: Shrink | L26: Store No | M26: Training Flag is false and Void Ticket is false and Total Loyalty Points Earned greater than 0 | N26: Count of Transactions Id, Sum Total Loyalty Points Earned. | O26: Missing No Sale Flag
A27: Store | E27: Drive Offs | F27: Count and Amount | G27: Store - DriveOff - Count and Amount | K27: Shrink | L27: Store No | M27: Training Mode is false and Void Ticket is false and Drive off flag is true | N27: Count of Transaction Id and Sum of Ticket Amount | O27: Missing No Sale Flag
A28: Store | E28: No Sale | F28: Count and Amount | G28: Store - NoSale - Count | I28: Cash In, Cash Out, Training… | J28: Need to list all that are required | K28: Shrink, Revenue, Productivity | L28: Store No | M28: Training Mode is false and Void Ticket is false and NoSale Flag is true | N28: Count of Transaction Id | O28: Missing No Sale Flag
A29: Store | B29: Reason Code | E29: No Sale | F29: Count and Amount | G29: Store - Reason - NoSale - Count | I29: As Above | L29: Store No, Transaction Type | M29: Training Mode is false and Void Ticket is false and NoSale Flag is true | N29: Count of Operator Action Transaction Id | O29: Missing No Sale Flag
A30: Store | E30: Price Checks | F30: Count | G30: Store - PriceChecks - Count | K30: Shrink, Productivity | L30: Store No | M30: Training Mode is false and Void Ticket is false and Fast Fact Total Price Enquiry Count greater than 0 | N30: Count of Transaction Id | O30: Missing No Sale Flag
A31: Store | E31: Zero priced Items | F31: Count | G31: Store - Zero PricedItems - Count and Amount | K31: Shrink | L31: Store No | M31: Training Mode is false and Item Amount Charged is 0 | N31: Sum Item Number of Items | O31: Missing No Sale Flag and Void Ticket Flag is false and Item Was Canceled is false
A32: Store | E32: Automatic Discounts Applied | F32: Count and Amount | G32: Store - AutomaticDiscountsApplied - Count and Amount | K32: Revenue | L32: Store No | M32: Training Mode is false and Void Ticket is false and Item Discount Reduction Reason Code greater than 0 and Item Discount Void Flag is 0 and Item Entry Mode is greater than 0 | N32: Sum Item Quantity Sum Item Dsicount Difference Amount | O32: Missing No Sale Flag
A33: Store | E33: Positive Discount Resulting in Price Increase | F33: Count and Amount | G33: Store - Positive Discount Resulting In PriceIncrease - Count and Amount | K33: Shrink, Revenue | L33: Store No | M33: Training Mode is false and Void Ticket is false and Item Discount Difference Amount less than 0 and Item Discount Voided Flg | N33: Sum Item Discount Quantity, Sum Item Dsicount Difference Amount | O33: Missing No Sale Flag
A34: Store | E34: Items Per Minute | F34: Count | K34: Productivity | L34: Store No | O34: Missing No Sale Flag
A35: Store | E35: Average Basket Size | F35: Amount | K35: Productivity | O35: Missing No Sale Flag
A36: Store | E36: Overs | F36: Count | G36: Store - Overs - Count and Amount | J36: Number of times tills have been counted as short | K36: Shrink | L36: Store No | M36: Training Mode is false and Void Ticket is false and Transaction Type is 11 and Ticket Amount not 0 | N36: Count of Transaction Id and Sum of Ticket Amount | O36: Missing No Sale Flag
A37: Store | E37: Shorts | F37: Count | G37: Store - Shorts - Count and Amount | J37: Number of times tills have been counted as over | K37: Shrink | L37: Store No | M37: 0Training Mode is false and Void Ticket is false and Transaction Type is 10 and Ticket Amount not 0 | N37: Count of Transaction Id and Sum of Ticket Amount | O37: Missing No Sale Flag
A38: Store | B38: Reason Code | E38: Item Discounts | F38: Count and Amount | H38: SRA
A39: Store | B39: Reason Code | E39: Transaction Discounts | F39: Count and Amount | H39: SRA
A40: Store | E40: Coupon | F40: Count and Amount | H40: SRA
...

Sheet Usage Metrics
A1: Key 1 | B1: Key 2 | C1: Metric Name | D1: Metric Value Types | E1: Notes
A2: Users | C2: Distinct Users | D2: Distinct Count
A3: Users | C3: UsageRate | D3: DistinctUsers / Total Active Users
A4: WorkView | C4: WorkViewCases | D4: Count of Workview items added to Case
A5: WorkView | C5: WorkViewItems | D5: Count of WorkViewItems generated
A6: WorkView | C6: WorkView Conversion | D6: WorkViewCases/WoprkViewItems
A7: Wokview | B7: Dispositon | C7: WorkViewDisposition | D7: Count of WorkView Item by Dipsoition Type
A8: Search | C8: SearchCount | D8: Number of user Searches created
A9: Seacrh | C9: SearchExecutiin | D9: Number of user searches executed
A10: InstantAnalytics | C10: IA Items | D10: Total IAs , Count of Workview items by IA
