Workbook

Sheet gap_inventory
A1: ISO 27001:2022 Annex A — 93 Control Gap Inventory
A2: Ctrl | B2: Title | C2: Theme | D2: DriftPOS-block? | E2: Current state | F2: Severity | G2: Hours | H2: Cost ($) | I2: Weeks | J2: Notes/owner
A3: 5.1 | B3: Policies for information security | C3: Org | E3: absent | F3: gap | G3: 40 | H3: =G3*assumptions!$B$3 -> 8000 | I3: =G3/(assumptions!$B$4*assumptions!$B$5) -> 0.44444444 | J3: No formal info-sec policy. Need to write one.
A4: 5.2 | B4: Information security roles and responsibilities | C4: Org | E4: weak | F4: gap | G4: 16 | H4: =G4*assumptions!$B$3 -> 3200 | I4: =G4/(assumptions!$B$4*assumptions!$B$5) -> 0.17777778 | J4: Roles informally held; not documented.
A5: 5.3 | B5: Segregation of duties | C5: Org | E5: weak | F5: partial | G5: 16 | H5: =G5*assumptions!$B$3 -> 3200 | I5: =G5/(assumptions!$B$4*assumptions!$B$5) -> 0.17777778 | J5: Senior engineers do everything; needs separation of admin from audit.
A6: 5.4 | B6: Management responsibilities | C6: Org | E6: weak | F6: partial | G6: 24 | H6: =G6*assumptions!$B$3 -> 4800 | I6: =G6/(assumptions!$B$4*assumptions!$B$5) -> 0.26666667 | J6: Owner is leader; need formal management commitment.
A7: 5.5 | B7: Contact with authorities | C7: Org | E7: weak | F7: partial | G7: 8 | H7: =G7*assumptions!$B$3 -> 1600 | I7: =G7/(assumptions!$B$4*assumptions!$B$5) -> 0.088888889 | J7: Knows local LE; needs documented contact list.
A8: 5.6 | B8: Contact with special interest groups | C8: Org | E8: absent | F8: gap | G8: 8 | H8: =G8*assumptions!$B$3 -> 1600 | I8: =G8/(assumptions!$B$4*assumptions!$B$5) -> 0.088888889 | J8: Not part of any infosec community.
A9: 5.7 | B9: Threat intelligence | C9: Org | E9: absent | F9: gap | G9: 16 | H9: =G9*assumptions!$B$3 -> 3200 | I9: =G9/(assumptions!$B$4*assumptions!$B$5) -> 0.17777778 | J9: No threat-intel program.
A10: 5.8 | B10: Information security in project management | C10: Org | E10: weak | F10: partial | G10: 8 | H10: =G10*assumptions!$B$3 -> 1600 | I10: =G10/(assumptions!$B$4*assumptions!$B$5) -> 0.088888889 | J10: Project mgmt informal; security not embedded.
A11: 5.9 | B11: Inventory of information and other associated assets | C11: Org | E11: weak | F11: gap | G11: 40 | H11: =G11*assumptions!$B$3 -> 8000 | I11: =G11/(assumptions!$B$4*assumptions!$B$5) -> 0.44444444 | J11: No formal asset inventory; deploy GCP CAI.
A12: 5.10 | B12: Acceptable use of information and other associated assets | C12: Org | E12: absent | F12: gap | G12: 8 | H12: =G12*assumptions!$B$3 -> 1600 | I12: =G12/(assumptions!$B$4*assumptions!$B$5) -> 0.088888889 | J12: Need AUP for staff and customers.
A13: 5.11 | B13: Return of assets | C13: Org | E13: moderate | F13: partial | G13: 8 | H13: =G13*assumptions!$B$3 -> 1600 | I13: =G13/(assumptions!$B$4*assumptions!$B$5) -> 0.088888889 | J13: Returns hardware on off-boarding; not documented.
A14: 5.12 | B14: Classification of information | C14: Org | E14: absent | F14: gap | G14: 16 | H14: =G14*assumptions!$B$3 -> 3200 | I14: =G14/(assumptions!$B$4*assumptions!$B$5) -> 0.17777778 | J14: No data classification scheme.
... A16: 5.14 | B16: Information transfer | C16: Org | E16: weak | F16: partial | G16: 16 | H16: =G16*assumptions!$B$3 -> 3200 | I16: =G16/(assumptions!$B$4*assumptions!$B$5) -> 0.17777778 | J16: Transfers happen via email; need governance.
A17: 5.15 | B17: Access control | C17: Org | D17: YES | E17: moderate | F17: partial | G17: 32 | H17: =G17*assumptions!$B$3 -> 6400 | I17: =G17/(assumptions!$B$4*assumptions!$B$5) -> 0.35555556 | J17: Counterpoint has access control; modernization needs IAM.
A18: 5.16 | B18: Identity management | C18: Org | E18: weak | F18: partial | G18: 24 | H18: =G18*assumptions!$B$3 -> 4800 | I18: =G18/(assumptions!$B$4*assumptions!$B$5) -> 0.26666667 | J18: Identity is per-system; need lifecycle process.
A19: 5.17 | B19: Authentication information | C19: Org | D19: YES | E19: moderate | F19: partial | G19: 24 | H19: =G19*assumptions!$B$3 -> 4800 | I19: =G19/(assumptions!$B$4*assumptions!$B$5) -> 0.26666667 | J19: Passwords/keys handled informally.
A20: 5.18 | B20: Access rights | C20: Org | E20: weak | F20: partial | G20: 16 | H20: =G20*assumptions!$B$3 -> 3200 | I20: =G20/(assumptions!$B$4*assumptions!$B$5) -> 0.17777778 | J20: Provisioning ad-hoc; de-provisioning has gaps.
A21: 5.19 | B21: Information security in supplier relationships | C21: Org | E21: absent | F21: gap | G21: 16 | H21: =G21*assumptions!$B$3 -> 3200 | I21: =G21/(assumptions!$B$4*assumptions!$B$5) -> 0.17777778 | J21: No vendor risk mgmt.
A22: 5.20 | B22: Addressing info-sec within supplier agreements | C22: Org | E22: weak | F22: partial | G22: 16 | H22: =G22*assumptions!$B$3 -> 3200 | I22: =G22/(assumptions!$B$4*assumptions!$B$5) -> 0.17777778 | J22: Some vendor contracts have security clauses; not all.
A23: 5.21 | B23: Managing info-sec in the ICT supply chain | C23: Org | E23: absent | F23: gap | G23: 16 | H23: =G23*assumptions!$B$3 -> 3200 | I23: =G23/(assumptions!$B$4*assumptions!$B$5) -> 0.17777778 | J23: Supply chain risk not analyzed.
A24: 5.22 | B24: Monitoring/review/change mgmt of supplier services | C24: Org | E24: absent | F24: gap | G24: 16 | H24: =G24*assumptions!$B$3 -> 3200 | I24: =G24/(assumptions!$B$4*assumptions!$B$5) -> 0.17777778 | J24: No vendor monitoring program.
A25: 5.23 | B25: Information security for use of cloud services | C25: Org | D25: YES | E25: absent | F25: gap | G25: 32 | H25: =G25*assumptions!$B$3 -> 6400 | I25: =G25/(assumptions!$B$4*assumptions!$B$5) -> 0.35555556 | J25: Cloud governance from scratch — Org policies needed.
A26: 5.24 | B26: IS incident management planning and preparation | C26: Org | D26: YES | E26: weak | F26: partial | G26: 24 | H26: =G26*assumptions!$B$3 -> 4800 | I26: =G26/(assumptions!$B$4*assumptions!$B$5) -> 0.26666667 | J26: Informal IR; need plan + tabletop.
A27: 5.25 | B27: Assessment and decision on info-sec events | C27: Org | E27: absent | F27: gap | G27: 16 | H27: =G27*assumptions!$B$3 -> 3200 | I27: =G27/(assumptions!$B$4*assumptions!$B$5) -> 0.17777778 | J27: No event triage process.
A28: 5.26 | B28: Response to info-sec incidents | C28: Org | E28: weak | F28: partial | G28: 16 | H28: =G28*assumptions!$B$3 -> 3200 | I28: =G28/(assumptions!$B$4*assumptions!$B$5) -> 0.17777778 | J28: Responds to incidents reactively; need process.
A29: 5.27 | B29: Learning from info-sec incidents | C29: Org | E29: weak | F29: partial | G29: 8 | H29: =G29*assumptions!$B$3 -> 1600 | I29: =G29/(assumptions!$B$4*assumptions!$B$5) -> 0.088888889 | J29: Postmortems happen verbally; not documented.
A30: 5.28 | B30: Collection of evidence | C30: Org | E30: weak | F30: gap | G30: 16 | H30: =G30*assumptions!$B$3 -> 3200 | I30: =G30/(assumptions!$B$4*assumptions!$B$5) -> 0.17777778 | J30: No forensic-readiness.
A31: 5.29 | B31: Information security during disruption | C31: Org | E31: weak | F31: partial | G31: 16 | H31: =G31*assumptions!$B$3 -> 3200 | I31: =G31/(assumptions!$B$4*assumptions!$B$5) -> 0.17777778 | J31: BCP exists for ops continuity, lacks infosec dimension.
A32: 5.30 | B32: ICT readiness for business continuity | C32: Org | E32: moderate | F32: partial | G32: 24 | H32: =G32*assumptions!$B$3 -> 4800 | I32: =G32/(assumptions!$B$4*assumptions!$B$5) -> 0.26666667 | J32: Backups exist; DR drills informal.
A33: 5.31 | B33: Legal/statutory/regulatory/contractual requirements | C33: Org | E33: moderate | F33: partial | G33: 16 | H33: =G33*assumptions!$B$3 -> 3200 | I33: =G33/(assumptions!$B$4*assumptions!$B$5) -> 0.17777778 | J33: Tax/PCI compliance tracked; broader regs less so.
A34: 5.32 | B34: Intellectual property rights | C34: Org | E34: moderate | F34: partial | G34: 8 | H34: =G34*assumptions!$B$3 -> 1600 | I34: =G34/(assumptions!$B$4*assumptions!$B$5) -> 0.088888889 | J34: IP policies for own work; not for customer customizations.
A35: 5.33 | B35: Protection of records | C35: Org | E35: moderate | F35: partial | G35: 16 | H35: =G35*assumptions!$B$3 -> 3200 | I35: =G35/(assumptions!$B$4*assumptions!$B$5) -> 0.17777778 | J35: Records kept; retention policy informal.
A36: 5.34 | B36: Privacy and protection of PII | C36: Org | D36: YES | E36: weak | F36: partial | G36: 32 | H36: =G36*assumptions!$B$3 -> 6400 | I36: =G36/(assumptions!$B$4*assumptions!$B$5) -> 0.35555556 | J36: PII handled per-customer convention; need centralized policy.
A37: 5.35 | B37: Independent review of info-sec | C37: Org | E37: absent | F37: gap | G37: 0 | H37: =G37*assumptions!$B$3 -> 0 | I37: =G37/(assumptions!$B$4*assumptions!$B$5) -> 0 | J37: Will become external audit by Growdirect (this!) — $0 internal cost.
A38: 5.36 | B38: Compliance with policies/rules/standards | C38: Org | E38: absent | F38: gap | G38: 16 | H38: =G38*assumptions!$B$3 -> 3200 | I38: =G38/(assumptions!$B$4*assumptions!$B$5) -> 0.17777778 | J38: No compliance monitoring.
A39: 5.37 | B39: Documented operating procedures | C39: Org | E39: weak | F39: partial | G39: 32 | H39: =G39*assumptions!$B$3 -> 6400 | I39: =G39/(assumptions!$B$4*assumptions!$B$5) -> 0.35555556 | J39: Some procedures documented; SOPs incomplete.
A40: 6.1 | B40: Screening | C40: People | E40: moderate | F40: partial | G40: 8 | H40: =G40*assumptions!$B$3 -> 1600 | I40: =G40/(assumptions!$B$4*assumptions!$B$5) -> 0.088888889 | J40: Background checks done; not formalized.
A41: 6.2 | B41: Terms and conditions of employment | C41: People | E41: moderate | F41: partial | G41: 8 | H41: =G41*assumptions!$B$3 -> 1600 | I41: =G41/(assumptions!$B$4*assumptions!$B$5) -> 0.088888889 | J41: Employment contracts include some security obligations.
...

Sheet severity_legend
A1: Severity legend (input options for column F)
A2: Value | B2: Meaning
A3: compliant | B3: Control is fully met. Evidence exists. No remediation required.
A4: partial | B4: Control is partially met. Some evidence exists; gaps in either coverage or documentation.
A5: gap | B5: Control is not met. Remediation required before certifiable posture.
A6: unknown | B6: Current state not yet known. Discovery item for next iteration.
A8: Current-state options (input column E):
A9: Value | B9: Meaning
A10: strong | B10: Native control in place; evidence-ready
A11: moderate | B11: Control in place but documentation gaps or partial coverage
A12: weak | B12: Practice exists but no formal control or evidence
A13: absent | B13: No practice; full implementation needed
A14: unknown | B14: Discovery required

Sheet assumptions
A1: Workload Estimator Assumptions
A2: Assumption | B2: Value | C2: Notes
A3: Loaded engineering rate ($/hr) | B3: 200 | C3: Should match cost-model loaded rate
A4: Effective FTE count for ISO remediation | B4: 3 | C4: How many FTEs working on Phase 2 in parallel
A5: Effective hours per FTE-week | B5: 30 | C5: 40 nominal − 25% overhead
A6: Compliance-pressure factor (for valuation discount) | B6: 0.7 | C6: See valuation-impact-formulas Formula 1
A7: Skill version | B7: saas-acquisition-diligence v1.0
A8: Linked cost-model run | B8: {path to cost-model-output.xlsx} | C8: Cross-reference

Sheet valuation_impact
A1: Valuation Impact — Gap-to-discount math
A2: Line | B2: Best ($) | C2: Expected ($) | D2: Worst ($)
A3: Total ISMS-gap remediation cost (linked from gap_inventory) | B3: =gap_inventory!H96*0.7 -> 235760 | C3: =gap_inventory!H96 -> 336800 | D3: =gap_inventory!H96*1.5 -> 505200
A4: Compliance-pressure factor | B4: 0.5 | C4: =assumptions!$B$6 -> 0.7 | D4: 1
A5: Discount-for-ISMS-gap (price reduction) | B5: =B3*B4 -> 117880 | C5: =C3*C4 -> 235760 | D5: =D3*D4 -> 505200
