Workbook

Sheet Master
A1: Loss Prevention Weekly Recap
A3: July 2-8, 2015
A5: Store Assessment Performance (>=90% or <80%)
A6: Region | B6: District | C6: Store Name | D6: Store # | E6: Score % | F6: Date | G6: Type | H6: Shrink Tier | I6: Cost Shrink % (Most Recent) | J6: Cost Shrink Goal %
A7: =IF(ISERROR(VLOOKUP($D7,'Alignment - No Action Needed'!$A$6:$F$1733,5,FALSE)),"",VLOOKUP($D7,'Alignment - No Action Needed'!$A$6:$F$1733,5,FALSE)) -> Midwest | B7: =IF(ISERROR(VLOOKUP($D7,'Alignment - No Action Needed'!$A$6:$F$1733,6,FALSE)),"",VLOOKUP($D7,'Alignment - No Action Needed'!$A$6:$F$1733,6,FALSE)) -> Wisconsin | C7: =IF(ISERROR(VLOOKUP($D7,'Alignment - No Action Needed'!$A$6:$F$1733,2,FALSE)),"",VLOOKUP($D7,'Alignment - No Action Needed'!$A$6:$F$1733,2,FALSE)) -> Brookfield | D7: 3008 | E7: 97.61 | F7: 42193.63 | G7: 2015 Golf Galaxy Audit | H7: =IF(ISERROR(VLOOKUP($D7,'Alignment - No Action Needed'!$A$6:$Z$1733,7,FALSE)),"",VLOOKUP($D7,'Alignment - No Action Needed'!$A$6:$Z$1733,7,FALSE)) -> G | I7: =IF(ISERROR(VLOOKUP($D7,'Alignment - No Action Needed'!$A$6:$Z$1733,8,FALSE)),"",VLOOKUP($D7,'Alignment - No Action Needed'!$A$6:$Z$1733,8,FALSE)) -> -0.0021848413 | J7: =IF(ISERROR(VLOOKUP($D7,'Alignment - No Action Needed'!$A$6:$Z$1733,9,FALSE)),"",VLOOKUP($D7,'Alignment - No Action Needed'!$A$6:$Z$1733,9,FALSE)) -> -0.00345
A8: =IF(ISERROR(VLOOKUP($D8,'Alignment - No Action Needed'!$A$6:$F$1733,5,FALSE)),"",VLOOKUP($D8,'Alignment - No Action Needed'!$A$6:$F$1733,5,FALSE)) -> Mid Atlantic | B8: =IF(ISERROR(VLOOKUP($D8,'Alignment - No Action Needed'!$A$6:$F$1733,6,FALSE)),"",VLOOKUP($D8,'Alignment - No Action Needed'!$A$6:$F$1733,6,FALSE)) -> Richmond | C8: =IF(ISERROR(VLOOKUP($D8,'Alignment - No Action Needed'!$A$6:$F$1733,2,FALSE)),"",VLOOKUP($D8,'Alignment - No Action Needed'!$A$6:$F$1733,2,FALSE)) -> Virginia Beach | D8: 3032 | E8: 97.61 | F8: 42192.616 | G8: 2015 Golf Galaxy Audit | H8: =IF(ISERROR(VLOOKUP($D8,'Alignment - No Action Needed'!$A$6:$Z$1733,7,FALSE)),"",VLOOKUP($D8,'Alignment - No Action Needed'!$A$6:$Z$1733,7,FALSE)) -> G | I8: =IF(ISERROR(VLOOKUP($D8,'Alignment - No Action Needed'!$A$6:$Z$1733,8,FALSE)),"",VLOOKUP($D8,'Alignment - No Action Needed'!$A$6:$Z$1733,8,FALSE)) -> -0.0015775306 | J8: =IF(ISERROR(VLOOKUP($D8,'Alignment - No Action Needed'!$A$6:$Z$1733,9,FALSE)),"",VLOOKUP($D8,'Alignment - No Action Needed'!$A$6:$Z$1733,9,FALSE)) -> -0.00345
A9: =IF(ISERROR(VLOOKUP($D9,'Alignment - No Action Needed'!$A$6:$F$1733,5,FALSE)),"",VLOOKUP($D9,'Alignment - No Action Needed'!$A$6:$F$1733,5,FALSE)) -> Southeast | B9: =IF(ISERROR(VLOOKUP($D9,'Alignment - No Action Needed'!$A$6:$F$1733,6,FALSE)),"",VLOOKUP($D9,'Alignment - No Action Needed'!$A$6:$F$1733,6,FALSE)) -> Florida South | C9: =IF(ISERROR(VLOOKUP($D9,'Alignment - No Action Needed'!$A$6:$F$1733,2,FALSE)),"",VLOOKUP($D9,'Alignment - No Action Needed'!$A$6:$F$1733,2,FALSE)) -> Pembroke Pines | D9: 3093 | E9: 95.13 | F9: 42188.73 | G9: 2015 Golf Galaxy Audit | H9: =IF(ISERROR(VLOOKUP($D9,'Alignment - No Action Needed'!$A$6:$Z$1733,7,FALSE)),"",VLOOKUP($D9,'Alignment - No Action Needed'!$A$6:$Z$1733,7,FALSE)) -> R | I9: =IF(ISERROR(VLOOKUP($D9,'Alignment - No Action Needed'!$A$6:$Z$1733,8,FALSE)),"",VLOOKUP($D9,'Alignment - No Action Needed'!$A$6:$Z$1733,8,FALSE)) -> -0.0172 | J9: =IF(ISERROR(VLOOKUP($D9,'Alignment - No Action Needed'!$A$6:$Z$1733,9,FALSE)),"",VLOOKUP($D9,'Alignment - No Action Needed'!$A$6:$Z$1733,9,FALSE)) -> -0.013
A10: =IF(ISERROR(VLOOKUP($D10,'Alignment - No Action Needed'!$A$6:$F$1733,5,FALSE)),"",VLOOKUP($D10,'Alignment - No Action Needed'!$A$6:$F$1733,5,FALSE)) -> Southwest | B10: =IF(ISERROR(VLOOKUP($D10,'Alignment - No Action Needed'!$A$6:$F$1733,6,FALSE)),"",VLOOKUP($D10,'Alignment - No Action Needed'!$A$6:$F$1733,6,FALSE)) -> Memphis | C10: =IF(ISERROR(VLOOKUP($D10,'Alignment - No Action Needed'!$A$6:$F$1733,2,FALSE)),"",VLOOKUP($D10,'Alignment - No Action Needed'!$A$6:$F$1733,2,FALSE)) -> Columbus, MS | D10: 1175 | E10: 93.69 | F10: 42191.986 | G10: 2015 LP Audit | H10: =IF(ISERROR(VLOOKUP($D10,'Alignment - No Action Needed'!$A$6:$Z$1733,7,FALSE)),"",VLOOKUP($D10,'Alignment - No Action Needed'!$A$6:$Z$1733,7,FALSE)) -> G | I10: =IF(ISERROR(VLOOKUP($D10,'Alignment - No Action Needed'!$A$6:$Z$1733,8,FALSE)),"",VLOOKUP($D10,'Alignment - No Action Needed'!$A$6:$Z$1733,8,FALSE)) -> -0.0061 | J10: =IF(ISERROR(VLOOKUP($D10,'Alignment - No Action Needed'!$A$6:$Z$1733,9,FALSE)),"",VLOOKUP($D10,'Alignment - No Action Needed'!$A$6:$Z$1733,9,FALSE)) -> -0.0084
A11: =IF(ISERROR(VLOOKUP($D11,'Alignment - No Action Needed'!$A$6:$F$1733,5,FALSE)),"",VLOOKUP($D11,'Alignment - No Action Needed'!$A$6:$F$1733,5,FALSE)) -> Southwest | B11: =IF(ISERROR(VLOOKUP($D11,'Alignment - No Action Needed'!$A$6:$F$1733,6,FALSE)),"",VLOOKUP($D11,'Alignment - No Action Needed'!$A$6:$F$1733,6,FALSE)) -> Memphis | C11: =IF(ISERROR(VLOOKUP($D11,'Alignment - No Action Needed'!$A$6:$F$1733,2,FALSE)),"",VLOOKUP($D11,'Alignment - No Action Needed'!$A$6:$F$1733,2,FALSE)) -> Conway, AR | D11: 608 | E11: 93.2 | F11: 42193.412 | G11: 2015 LP Audit | H11: =IF(ISERROR(VLOOKUP($D11,'Alignment - No Action Needed'!$A$6:$Z$1733,7,FALSE)),"",VLOOKUP($D11,'Alignment - No Action Needed'!$A$6:$Z$1733,7,FALSE)) -> Y | I11: =IF(ISERROR(VLOOKUP($D11,'Alignment - No Action Needed'!$A$6:$Z$1733,8,FALSE)),"",VLOOKUP($D11,'Alignment - No Action Needed'!$A$6:$Z$1733,8,FALSE)) -> -0.0117 | J11: =IF(ISERROR(VLOOKUP($D11,'Alignment - No Action Needed'!$A$6:$Z$1733,9,FALSE)),"",VLOOKUP($D11,'Alignment - No Action Needed'!$A$6:$Z$1733,9,FALSE)) -> -0.0062
A12: =IF(ISERROR(VLOOKUP($D12,'Alignment - No Action Needed'!$A$6:$F$1733,5,FALSE)),"",VLOOKUP($D12,'Alignment - No Action Needed'!$A$6:$F$1733,5,FALSE)) -> Southwest | B12: =IF(ISERROR(VLOOKUP($D12,'Alignment - No Action Needed'!$A$6:$F$1733,6,FALSE)),"",VLOOKUP($D12,'Alignment - No Action Needed'!$A$6:$F$1733,6,FALSE)) -> New Orleans | C12: =IF(ISERROR(VLOOKUP($D12,'Alignment - No Action Needed'!$A$6:$F$1733,2,FALSE)),"",VLOOKUP($D12,'Alignment - No Action Needed'!$A$6:$F$1733,2,FALSE)) -> Baton Rouge | D12: 399 | E12: 92.61 | F12: 42187.533 | G12: 2015 LP Audit | H12: =IF(ISERROR(VLOOKUP($D12,'Alignment - No Action Needed'!$A$6:$Z$1733,7,FALSE)),"",VLOOKUP($D12,'Alignment - No Action Needed'!$A$6:$Z$1733,7,FALSE)) -> G | I12: =IF(ISERROR(VLOOKUP($D12,'Alignment - No Action Needed'!$A$6:$Z$1733,8,FALSE)),"",VLOOKUP($D12,'Alignment - No Action Needed'!$A$6:$Z$1733,8,FALSE)) -> -0.0061 | J12: =IF(ISERROR(VLOOKUP($D12,'Alignment - No Action Needed'!$A$6:$Z$1733,9,FALSE)),"",VLOOKUP($D12,'Alignment - No Action Needed'!$A$6:$Z$1733,9,FALSE)) -> -0.0064
A13: =IF(ISERROR(VLOOKUP($D13,'Alignment - No Action Needed'!$A$6:$F$1733,5,FALSE)),"",VLOOKUP($D13,'Alignment - No Action Needed'!$A$6:$F$1733,5,FALSE)) -> Ohio Valley | B13: =IF(ISERROR(VLOOKUP($D13,'Alignment - No Action Needed'!$A$6:$F$1733,6,FALSE)),"",VLOOKUP($D13,'Alignment - No Action Needed'!$A$6:$F$1733,6,FALSE)) -> Cincinnati | C13: =IF(ISERROR(VLOOKUP($D13,'Alignment - No Action Needed'!$A$6:$F$1733,2,FALSE)),"",VLOOKUP($D13,'Alignment - No Action Needed'!$A$6:$F$1733,2,FALSE)) -> Western Hills | D13: 74 | E13: 92.46 | F13: 42192.645 | G13: 2015 LP Audit | H13: =IF(ISERROR(VLOOKUP($D13,'Alignment - No Action Needed'!$A$6:$Z$1733,7,FALSE)),"",VLOOKUP($D13,'Alignment - No Action Needed'!$A$6:$Z$1733,7,FALSE)) -> R | I13: =IF(ISERROR(VLOOKUP($D13,'Alignment - No Action Needed'!$A$6:$Z$1733,8,FALSE)),"",VLOOKUP($D13,'Alignment - No Action Needed'!$A$6:$Z$1733,8,FALSE)) -> -0.011943249 | J13: =IF(ISERROR(VLOOKUP($D13,'Alignment - No Action Needed'!$A$6:$Z$1733,9,FALSE)),"",VLOOKUP($D13,'Alignment - No Action Needed'!$A$6:$Z$1733,9,FALSE)) -> -0.012108011
A14: =IF(ISERROR(VLOOKUP($D14,'Alignment - No Action Needed'!$A$6:$F$1733,5,FALSE)),"",VLOOKUP($D14,'Alignment - No Action Needed'!$A$6:$F$1733,5,FALSE)) -> Ohio Valley | B14: =IF(ISERROR(VLOOKUP($D14,'Alignment - No Action Needed'!$A$6:$F$1733,6,FALSE)),"",VLOOKUP($D14,'Alignment - No Action Needed'!$A$6:$F$1733,6,FALSE)) -> Columbus | C14: =IF(ISERROR(VLOOKUP($D14,'Alignment - No Action Needed'!$A$6:$F$1733,2,FALSE)),"",VLOOKUP($D14,'Alignment - No Action Needed'!$A$6:$F$1733,2,FALSE)) -> Columbus/Easton RELO 3069 | D14: 3118 | E14: 92.34 | F14: 42187.382 | G14: 2015 Golf Galaxy Audit | H14: =IF(ISERROR(VLOOKUP($D14,'Alignment - No Action Needed'!$A$6:$Z$1733,7,FALSE)),"",VLOOKUP($D14,'Alignment - No Action Needed'!$A$6:$Z$1733,7,FALSE)) -> New | I14: =IF(ISERROR(VLOOKUP($D14,'Alignment - No Action Needed'!$A$6:$Z$1733,8,FALSE)),"",VLOOKUP($D14,'Alignment - No Action Needed'!$A$6:$Z$1733,8,FALSE)) -> N/A | J14: =IF(ISERROR(VLOOKUP($D14,'Alignment - No Action Needed'!$A$6:$Z$1733,9,FALSE)),"",VLOOKUP($D14,'Alignment - No Action Needed'!$A$6:$Z$1733,9,FALSE)) -> -0.0045
A15: =IF(ISERROR(VLOOKUP($D15,'Alignment - No Action Needed'!$A$6:$F$1733,5,FALSE)),"",VLOOKUP($D15,'Alignment - No Action Needed'!$A$6:$F$1733,5,FALSE)) -> Ohio Valley | B15: =IF(ISERROR(VLOOKUP($D15,'Alignment - No Action Needed'!$A$6:$F$1733,6,FALSE)),"",VLOOKUP($D15,'Alignment - No Action Needed'!$A$6:$F$1733,6,FALSE)) -> Columbus | C15: =IF(ISERROR(VLOOKUP($D15,'Alignment - No Action Needed'!$A$6:$F$1733,2,FALSE)),"",VLOOKUP($D15,'Alignment - No Action Needed'!$A$6:$F$1733,2,FALSE)) -> Tuttle Crossing | D15: 3009 | E15: 92.08 | F15: 42192.543 | G15: 2015 Golf Galaxy Audit | H15: =IF(ISERROR(VLOOKUP($D15,'Alignment - No Action Needed'!$A$6:$Z$1733,7,FALSE)),"",VLOOKUP($D15,'Alignment - No Action Needed'!$A$6:$Z$1733,7,FALSE)) -> G | I15: =IF(ISERROR(VLOOKUP($D15,'Alignment - No Action Needed'!$A$6:$Z$1733,8,FALSE)),"",VLOOKUP($D15,'Alignment - No Action Needed'!$A$6:$Z$1733,8,FALSE)) -> -0.0022915435 | J15: =IF(ISERROR(VLOOKUP($D15,'Alignment - No Action Needed'!$A$6:$Z$1733,9,FALSE)),"",VLOOKUP($D15,'Alignment - No Action Needed'!$A$6:$Z$1733,9,FALSE)) -> -0.00345
A16: =IF(ISERROR(VLOOKUP($D16,'Alignment - No Action Needed'!$A$6:$F$1733,5,FALSE)),"",VLOOKUP($D16,'Alignment - No Action Needed'!$A$6:$F$1733,5,FALSE)) -> Midwest | B16: =IF(ISERROR(VLOOKUP($D16,'Alignment - No Action Needed'!$A$6:$F$1733,6,FALSE)),"",VLOOKUP($D16,'Alignment - No Action Needed'!$A$6:$F$1733,6,FALSE)) -> Chicago South | C16: =IF(ISERROR(VLOOKUP($D16,'Alignment - No Action Needed'!$A$6:$F$1733,2,FALSE)),"",VLOOKUP($D16,'Alignment - No Action Needed'!$A$6:$F$1733,2,FALSE)) -> Oswego | D16: 312 | E16: 92.02 | F16: 42187.923 | G16: 2015 LP Audit | H16: =IF(ISERROR(VLOOKUP($D16,'Alignment - No Action Needed'!$A$6:$Z$1733,7,FALSE)),"",VLOOKUP($D16,'Alignment - No Action Needed'!$A$6:$Z$1733,7,FALSE)) -> Y | I16: =IF(ISERROR(VLOOKUP($D16,'Alignment - No Action Needed'!$A$6:$Z$1733,8,FALSE)),"",VLOOKUP($D16,'Alignment - No Action Needed'!$A$6:$Z$1733,8,FALSE)) -> -0.0071993596 | J16: =IF(ISERROR(VLOOKUP($D16,'Alignment - No Action Needed'!$A$6:$Z$1733,9,FALSE)),"",VLOOKUP($D16,'Alignment - No Action Needed'!$A$6:$Z$1733,9,FALSE)) -> -0.0072663602
A17: =IF(ISERROR(VLOOKUP($D17,'Alignment - No Action Needed'!$A$6:$F$1733,5,FALSE)),"",VLOOKUP($D17,'Alignment - No Action Needed'!$A$6:$F$1733,5,FALSE)) -> Southeast | B17: =IF(ISERROR(VLOOKUP($D17,'Alignment - No Action Needed'!$A$6:$F$1733,6,FALSE)),"",VLOOKUP($D17,'Alignment - No Action Needed'!$A$6:$F$1733,6,FALSE)) -> Florida South | C17: =IF(ISERROR(VLOOKUP($D17,'Alignment - No Action Needed'!$A$6:$F$1733,2,FALSE)),"",VLOOKUP($D17,'Alignment - No Action Needed'!$A$6:$F$1733,2,FALSE)) -> Pembroke Pines | D17: 669 | E17: 91.97 | F17: 42187.683 | G17: 2015 LP Audit | H17: =IF(ISERROR(VLOOKUP($D17,'Alignment - No Action Needed'!$A$6:$Z$1733,7,FALSE)),"",VLOOKUP($D17,'Alignment - No Action Needed'!$A$6:$Z$1733,7,FALSE)) -> R | I17: =IF(ISERROR(VLOOKUP($D17,'Alignment - No Action Needed'!$A$6:$Z$1733,8,FALSE)),"",VLOOKUP($D17,'Alignment - No Action Needed'!$A$6:$Z$1733,8,FALSE)) -> -0.022415847 | J17: =IF(ISERROR(VLOOKUP($D17,'Alignment - No Action Needed'!$A$6:$Z$1733,9,FALSE)),"",VLOOKUP($D17,'Alignment - No Action Needed'!$A$6:$Z$1733,9,FALSE)) -> -0.0145
A18: =IF(ISERROR(VLOOKUP($D18,'Alignment - No Action Needed'!$A$6:$F$1733,5,FALSE)),"",VLOOKUP($D18,'Alignment - No Action Needed'!$A$6:$F$1733,5,FALSE)) -> Midwest | B18: =IF(ISERROR(VLOOKUP($D18,'Alignment - No Action Needed'!$A$6:$F$1733,6,FALSE)),"",VLOOKUP($D18,'Alignment - No Action Needed'!$A$6:$F$1733,6,FALSE)) -> Wisconsin | C18: =IF(ISERROR(VLOOKUP($D18,'Alignment - No Action Needed'!$A$6:$F$1733,2,FALSE)),"",VLOOKUP($D18,'Alignment - No Action Needed'!$A$6:$F$1733,2,FALSE)) -> West Madison | D18: 178 | E18: 91.67 | F18: 42192.505 | G18: 2015 LP Audit | H18: =IF(ISERROR(VLOOKUP($D18,'Alignment - No Action Needed'!$A$6:$Z$1733,7,FALSE)),"",VLOOKUP($D18,'Alignment - No Action Needed'!$A$6:$Z$1733,7,FALSE)) -> Y | I18: =IF(ISERROR(VLOOKUP($D18,'Alignment - No Action Needed'!$A$6:$Z$1733,8,FALSE)),"",VLOOKUP($D18,'Alignment - No Action Needed'!$A$6:$Z$1733,8,FALSE)) -> -0.0054 | J18: =IF(ISERROR(VLOOKUP($D18,'Alignment - No Action Needed'!$A$6:$Z$1733,9,FALSE)),"",VLOOKUP($D18,'Alignment - No Action Needed'!$A$6:$Z$1733,9,FALSE)) -> -0.0064
... A25: =IF(ISERROR(VLOOKUP($D25,'Alignment - No Action Needed'!$A$6:$F$1733,5,FALSE)),"",VLOOKUP($D25,'Alignment - No Action Needed'!$A$6:$F$1733,5,FALSE)) -> Ohio Valley | B25: =IF(ISERROR(VLOOKUP($D25,'Alignment - No Action Needed'!$A$6:$F$1733,6,FALSE)),"",VLOOKUP($D25,'Alignment - No Action Needed'!$A$6:$F$1733,6,FALSE)) -> Louisville | C25: =IF(ISERROR(VLOOKUP($D25,'Alignment - No Action Needed'!$A$6:$F$1733,2,FALSE)),"",VLOOKUP($D25,'Alignment - No Action Needed'!$A$6:$F$1733,2,FALSE)) -> Frankfort | D25: 1140 | E25: 75.8 | F25: 42192.845 | G25: 2015 LP Audit | H25: =IF(ISERROR(VLOOKUP($D25,'Alignment - No Action Needed'!$A$6:$Z$1733,7,FALSE)),"",VLOOKUP($D25,'Alignment - No Action Needed'!$A$6:$Z$1733,7,FALSE)) -> G | I25: =IF(ISERROR(VLOOKUP($D25,'Alignment - No Action Needed'!$A$6:$Z$1733,8,FALSE)),"",VLOOKUP($D25,'Alignment - No Action Needed'!$A$6:$Z$1733,8,FALSE)) -> -0.0082 | J25: =IF(ISERROR(VLOOKUP($D25,'Alignment - No Action Needed'!$A$6:$Z$1733,9,FALSE)),"",VLOOKUP($D25,'Alignment - No Action Needed'!$A$6:$Z$1733,9,FALSE)) -> -0.0084
A27: Critical Incidents
A28: Region | B28: District | C28: Store Name | D28: Store # | E28: Date | F28: Incident Type | G28: Comments
A29: =IF(ISERROR(VLOOKUP($D29,'Alignment - No Action Needed'!$A$6:$F$1733,5,FALSE)),"",VLOOKUP($D29,'Alignment - No Action Needed'!$A$6:$F$1733,5,FALSE)) -> Southwest | B29: =IF(ISERROR(VLOOKUP($D29,'Alignment - No Action Needed'!$A$6:$F$1733,6,FALSE)),"",VLOOKUP($D29,'Alignment - No Action Needed'!$A$6:$F$1733,6,FALSE)) -> Dallas | C29: =IF(ISERROR(VLOOKUP($D29,'Alignment - No Action Needed'!$A$6:$F$1733,2,FALSE)),"",VLOOKUP($D29,'Alignment - No Action Needed'!$A$6:$F$1733,2,FALSE)) -> Park Lane | D29: 709 | E29: 42193.677 | F29: Unaccounted for Firearm | G29: A shipment of handguns is missing
A30: =IF(ISERROR(VLOOKUP($D30,'Alignment - No Action Needed'!$A$6:$F$1733,5,FALSE)),"",VLOOKUP($D30,'Alignment - No Action Needed'!$A$6:$F$1733,5,FALSE)) -> Northeast | B30: =IF(ISERROR(VLOOKUP($D30,'Alignment - No Action Needed'!$A$6:$F$1733,6,FALSE)),"",VLOOKUP($D30,'Alignment - No Action Needed'!$A$6:$F$1733,6,FALSE)) -> New Jersey North | C30: =IF(ISERROR(VLOOKUP($D30,'Alignment - No Action Needed'!$A$6:$F$1733,2,FALSE)),"",VLOOKUP($D30,'Alignment - No Action Needed'!$A$6:$F$1733,2,FALSE)) -> Union, NJ | D30: 1032 | E30: 42192.583 | F30: Inspection: Firearms
A31: =IF(ISERROR(VLOOKUP($D31,'Alignment - No Action Needed'!$A$6:$F$1733,5,FALSE)),"",VLOOKUP($D31,'Alignment - No Action Needed'!$A$6:$F$1733,5,FALSE)) -> Midwest | B31: =IF(ISERROR(VLOOKUP($D31,'Alignment - No Action Needed'!$A$6:$F$1733,6,FALSE)),"",VLOOKUP($D31,'Alignment - No Action Needed'!$A$6:$F$1733,6,FALSE)) -> Omaha | C31: =IF(ISERROR(VLOOKUP($D31,'Alignment - No Action Needed'!$A$6:$F$1733,2,FALSE)),"",VLOOKUP($D31,'Alignment - No Action Needed'!$A$6:$F$1733,2,FALSE)) -> West Des Moines | D31: 1101 | E31: 42191.417 | F31: Incident General (Critical Smart Alert) | G31: An associate who attempted to purchase a firearm committed suicide, the firearm purchase was delayed and was not transferred by the store.
A33: Investigations
A34: Region | B34: DE Case Count | C34: Prosecution Count | D34: PV Case Count | E34: Total Cases | F34: Total $ | G34: Comments
A35: Mid Atlantic | B35: =VLOOKUP($A35,'Investigations by Region'!$H$6:$M$25,2,FALSE) -> 1 | C35: =VLOOKUP($A35,'Investigations by Region'!$H$6:$M$25,3,FALSE) -> 0 | D35: =VLOOKUP($A35,'Investigations by Region'!$H$6:$M$25,4,FALSE) -> 0 | E35: =VLOOKUP($A35,'Investigations by Region'!$H$6:$M$25,5,FALSE) -> 1 | F35: =VLOOKUP($A35,'Investigations by Region'!$H$6:$M$25,6,FALSE) -> 2500 | G35: Gift Card Fraud
A36: Midwest | B36: =VLOOKUP($A36,'Investigations by Region'!$H$6:$M$25,2,FALSE) -> 1 | C36: =VLOOKUP($A36,'Investigations by Region'!$H$6:$M$25,3,FALSE) -> 0 | D36: =VLOOKUP($A36,'Investigations by Region'!$H$6:$M$25,4,FALSE) -> 0 | E36: =VLOOKUP($A36,'Investigations by Region'!$H$6:$M$25,5,FALSE) -> 1 | F36: =VLOOKUP($A36,'Investigations by Region'!$H$6:$M$25,6,FALSE) -> 1090 | G36: Unauthorized Markdowns
A37: Northeast | B37: =VLOOKUP($A37,'Investigations by Region'!$H$6:$M$25,2,FALSE) -> 2 | C37: =VLOOKUP($A37,'Investigations by Region'!$H$6:$M$25,3,FALSE) -> 0 | D37: =VLOOKUP($A37,'Investigations by Region'!$H$6:$M$25,4,FALSE) -> 1 | E37: =VLOOKUP($A37,'Investigations by Region'!$H$6:$M$25,5,FALSE) -> 3 | F37: =VLOOKUP($A37,'Investigations by Region'!$H$6:$M$25,6,FALSE) -> 105.4875 | G37: Merchandise Theft, Employee Discount Abuse, Unauthorized Markdowns
A38: Ohio Valley | B38: =VLOOKUP($A38,'Investigations by Region'!$H$6:$M$25,2,FALSE) -> 0 | C38: =VLOOKUP($A38,'Investigations by Region'!$H$6:$M$25,3,FALSE) -> 0 | D38: =VLOOKUP($A38,'Investigations by Region'!$H$6:$M$25,4,FALSE) -> 0 | E38: =VLOOKUP($A38,'Investigations by Region'!$H$6:$M$25,5,FALSE) -> 0 | F38: =VLOOKUP($A38,'Investigations by Region'!$H$6:$M$25,6,FALSE) -> 0
A39: Southeast | B39: =VLOOKUP($A39,'Investigations by Region'!$H$6:$M$25,2,FALSE) -> 2 | C39: =VLOOKUP($A39,'Investigations by Region'!$H$6:$M$25,3,FALSE) -> 0 | D39: =VLOOKUP($A39,'Investigations by Region'!$H$6:$M$25,4,FALSE) -> 0 | E39: =VLOOKUP($A39,'Investigations by Region'!$H$6:$M$25,5,FALSE) -> 2 | F39: =VLOOKUP($A39,'Investigations by Region'!$H$6:$M$25,6,FALSE) -> 40 | G39: Gift Card Fraud, Unauthorized Markdowns
A40: Southwest | B40: =VLOOKUP($A40,'Investigations by Region'!$H$6:$M$25,2,FALSE) -> 0 | C40: =VLOOKUP($A40,'Investigations by Region'!$H$6:$M$25,3,FALSE) -> 0 | D40: =VLOOKUP($A40,'Investigations by Region'!$H$6:$M$25,4,FALSE) -> 0 | E40: =VLOOKUP($A40,'Investigations by Region'!$H$6:$M$25,5,FALSE) -> 0 | F40: =VLOOKUP($A40,'Investigations by Region'!$H$6:$M$25,6,FALSE) -> 0
A41: West | B41: =VLOOKUP($A41,'Investigations by Region'!$H$6:$M$25,2,FALSE) -> 2 | C41: =VLOOKUP($A41,'Investigations by Region'!$H$6:$M$25,3,FALSE) -> 1 | D41: =VLOOKUP($A41,'Investigations by Region'!$H$6:$M$25,4,FALSE) -> 0 | E41: =VLOOKUP($A41,'Investigations by Region'!$H$6:$M$25,5,FALSE) -> 2 | F41: =VLOOKUP($A41,'Investigations by Region'!$H$6:$M$25,6,FALSE) -> 2859.82 | G41: Passing Merchandise, Merchandise Theft
A42: F&S | B42: =VLOOKUP($A42,'Investigations by Region'!$H$6:$M$25,2,FALSE) -> 0 | C42: =VLOOKUP($A42,'Investigations by Region'!$H$6:$M$25,3,FALSE) -> 0 | D42: =VLOOKUP($A42,'Investigations by Region'!$H$6:$M$25,4,FALSE) -> 0 | E42: =VLOOKUP($A42,'Investigations by Region'!$H$6:$M$25,5,FALSE) -> 0 | F42: =VLOOKUP($A42,'Investigations by Region'!$H$6:$M$25,6,FALSE) -> 0
A43: Totals | B43: =SUM(B35:B42) -> 8 | C43: =SUM(C35:C42) -> 1 | D43: =SUM(D35:D42) -> 1 | E43: =SUM(E35:E42) -> 9 | F43: =SUM(F35:F42) -> 6595.3075
A47: Theft Deterrence and Recoveries (>$249)
A48: Region | B48: District | C48: Store Name | D48: Store # | E48: Department | F48: Total $ | G48: Date | H48: Description of Incident
A49: =IF(ISERROR(VLOOKUP($D49,'Alignment - No Action Needed'!$A$6:$F$1733,5,FALSE)),"",VLOOKUP($D49,'Alignment - No Action Needed'!$A$6:$F$1733,5,FALSE)) -> Midwest | B49: =IF(ISERROR(VLOOKUP($D49,'Alignment - No Action Needed'!$A$6:$F$1733,6,FALSE)),"",VLOOKUP($D49,'Alignment - No Action Needed'!$A$6:$F$1733,6,FALSE)) -> Chicago South | C49: =IF(ISERROR(VLOOKUP($D49,'Alignment - No Action Needed'!$A$6:$F$1733,2,FALSE)),"",VLOOKUP($D49,'Alignment - No Action Needed'!$A$6:$F$1733,2,FALSE)) -> Chicago | D49: 1133 | E49: Apparel | F49: 255.96 | G49: 42192.553 | H49: Two customers damaged Nike product while trying to remove the ink tags. They were deterred by exceptional customer service.
A50: =IF(ISERROR(VLOOKUP($D50,'Alignment - No Action Needed'!$A$6:$F$1733,5,FALSE)),"",VLOOKUP($D50,'Alignment - No Action Needed'!$A$6:$F$1733,5,FALSE)) -> Ohio Valley | B50: =IF(ISERROR(VLOOKUP($D50,'Alignment - No Action Needed'!$A$6:$F$1733,6,FALSE)),"",VLOOKUP($D50,'Alignment - No Action Needed'!$A$6:$F$1733,6,FALSE)) -> Cincinnati | C50: =IF(ISERROR(VLOOKUP($D50,'Alignment - No Action Needed'!$A$6:$F$1733,2,FALSE)),"",VLOOKUP($D50,'Alignment - No Action Needed'!$A$6:$F$1733,2,FALSE)) -> Florence KY | D50: 70 | E50: Apparel | F50: 344 | G50: 42191.469 | H50: A customer was suspected of trying to take several apparel items. He was deterred by exceptional customer service.
A51: =IF(ISERROR(VLOOKUP($D51,'Alignment - No Action Needed'!$A$6:$F$1733,5,FALSE)),"",VLOOKUP($D51,'Alignment - No Action Needed'!$A$6:$F$1733,5,FALSE)) -> Southeast | B51: =IF(ISERROR(VLOOKUP($D51,'Alignment - No Action Needed'!$A$6:$F$1733,6,FALSE)),"",VLOOKUP($D51,'Alignment - No Action Needed'!$A$6:$F$1733,6,FALSE)) -> Atlanta East | C51: =IF(ISERROR(VLOOKUP($D51,'Alignment - No Action Needed'!$A$6:$F$1733,2,FALSE)),"",VLOOKUP($D51,'Alignment - No Action Needed'!$A$6:$F$1733,2,FALSE)) -> Lenox | D51: 418 | E51: Apparel | F51: 427 | G51: 42190.708 | H51: A bag full of Nike product was discovered, staged by the front door.
A52: =IF(ISERROR(VLOOKUP($D52,'Alignment - No Action Needed'!$A$6:$F$1733,5,FALSE)),"",VLOOKUP($D52,'Alignment - No Action Needed'!$A$6:$F$1733,5,FALSE)) -> Midwest | B52: =IF(ISERROR(VLOOKUP($D52,'Alignment - No Action Needed'!$A$6:$F$1733,6,FALSE)),"",VLOOKUP($D52,'Alignment - No Action Needed'!$A$6:$F$1733,6,FALSE)) -> Indianapolis | C52: =IF(ISERROR(VLOOKUP($D52,'Alignment - No Action Needed'!$A$6:$F$1733,2,FALSE)),"",VLOOKUP($D52,'Alignment - No Action Needed'!$A$6:$F$1733,2,FALSE)) -> Castleton | D52: 416 | E52: Apparel | F52: 464.96 | G52: 42192.812 | H52: A customer was witnessed by in store LP cutting ink tags off various apparel product with wire snips. She dumped all the product when she noticed she was being watched.
A53: =IF(ISERROR(VLOOKUP($D53,'Alignment - No Action Needed'!$A$6:$F$1733,5,FALSE)),"",VLOOKUP($D53,'Alignment - No Action Needed'!$A$6:$F$1733,5,FALSE)) -> West | B53: =IF(ISERROR(VLOOKUP($D53,'Alignment - No Action Needed'!$A$6:$F$1733,6,FALSE)),"",VLOOKUP($D53,'Alignment - No Action Needed'!$A$6:$F$1733,6,FALSE)) -> Northern California | C53: =IF(ISERROR(VLOOKUP($D53,'Alignment - No Action Needed'!$A$6:$F$1733,2,FALSE)),"",VLOOKUP($D53,'Alignment - No Action Needed'!$A$6:$F$1733,2,FALSE)) -> Chico | D53: 1089 | E53: Apparel | F53: 635.87 | G53: 42187 | H53: A customer was seen collecting various items from all over the store in a cart. He was deterred by exceptional customer service as he made his way to the front entrance.
...

Sheet Investigations by Region
A2: Paste LPMS report in columns A-E and everything will update | V2: Prosecuted
A5: Store # | B5: CaseNo | C5: CaseType | D5: TotalStolen | E5: ActionTaken | H5: Region | I5: DE | J5: Prosecution Count | K5: PV | L5: Total Cases | M5: Total $ Value | N5: Region DE | O5: Region PV | P5: Region TRUE | R5: Region | S5: Case Type | T5: Region Type | U5: Ttl $ | V5: Action | W5: Region Action
A6: 1072 | B6: DE-15-01072-2 | C6: Passing Merchandise | D6: 2843.78 | E6: Terminated - Prosecuted | H6: Mid Atlantic | I6: =COUNTIF($T$6:$T$103,N6) -> 1 | J6: =COUNTIF($W$6:$W$103,P6) -> 0 | K6: =COUNTIF($T$6:$T$103,O6) -> 0 | L6: =I6+K6 -> 1 | M6: =SUMIF($R$6:$R$103,H6,$U$6:$U$103) -> 2500 | N6: =H6&"-"&$I$5 -> Mid Atlantic-DE | O6: =H6&"-"&$K$5 -> Mid Atlantic-PV | P6: =H6&"-"&"TRUE" -> Mid Atlantic-TRUE | R6: =IF(ISERROR(VLOOKUP(A6,'Alignment - No Action Needed'!$A$6:$F$1733,5,FALSE)),"",VLOOKUP(A6,'Alignment - No Action Needed'!$A$6:$F$1733,5,FALSE)) -> West | S6: =LEFT(B6,2) -> DE | T6: =R6&"-"&S6 -> West-DE | U6: =D6 -> 2843.78 | V6: =ISNUMBER(SEARCH($V$2,E6)) -> TRUE | W6: =R6&"-"&V6 -> West-TRUE
A7: 1076 | B7: DE-15-01076-2 | C7: Merchandise Theft | D7: 16.04 | E7: Terminated - Released | H7: Midwest | I7: =COUNTIF($T$6:$T$103,N7) -> 1 | J7: =COUNTIF($W$6:$W$103,P7) -> 0 | K7: =COUNTIF($T$6:$T$103,O7) -> 0 | L7: =I7+K7 -> 1 | M7: =SUMIF($R$6:$R$103,H7,$U$6:$U$103) -> 1090 | N7: =H7&"-"&$I$5 -> Midwest-DE | O7: =H7&"-"&$K$5 -> Midwest-PV | P7: =H7&"-"&"TRUE" -> Midwest-TRUE | R7: =IF(ISERROR(VLOOKUP(A7,'Alignment - No Action Needed'!$A$6:$F$1733,5,FALSE)),"",VLOOKUP(A7,'Alignment - No Action Needed'!$A$6:$F$1733,5,FALSE)) -> West | S7: =LEFT(B7,2) -> DE | T7: =R7&"-"&S7 -> West-DE | U7: =D7 -> 16.04 | V7: =ISNUMBER(SEARCH($V$2,E7)) -> FALSE | W7: =R7&"-"&V7 -> West-FALSE
A8: 181 | B8: DE-15-00181-1 | C8: Unauthorized Markdowns | D8: 1090 | E8: Phone Interview - Terminated/Released | H8: Northeast | I8: =COUNTIF($T$6:$T$103,N9) -> 2 | J8: =COUNTIF($W$6:$W$103,P9) -> 0 | K8: =COUNTIF($T$6:$T$103,O9) -> 1 | L8: =I8+K8 -> 3 | M8: =SUMIF($R$6:$R$103,H8,$U$6:$U$103) -> 105.4875 | N8: =#REF!&"-"&$I$5 -> #REF! | O8: =#REF!&"-"&$K$5 -> #REF! | P8: =#REF!&"-"&"TRUE" -> #REF! | R8: =IF(ISERROR(VLOOKUP(A8,'Alignment - No Action Needed'!$A$6:$F$1733,5,FALSE)),"",VLOOKUP(A8,'Alignment - No Action Needed'!$A$6:$F$1733,5,FALSE)) -> Midwest | S8: =LEFT(B8,2) -> DE | T8: =R8&"-"&S8 -> Midwest-DE | U8: =D8 -> 1090 | V8: =ISNUMBER(SEARCH($V$2,E8)) -> FALSE | W8: =R8&"-"&V8 -> Midwest-FALSE
A9: 414 | B9: DE-15-00414-2 | C9: Gift/Merchandise Card Fraud | D9: 2500 | E9: Terminated - Released | H9: Ohio Valley | I9: =COUNTIF($T$6:$T$103,N10) -> 0 | J9: =COUNTIF($W$6:$W$103,P10) -> 0 | K9: =COUNTIF($T$6:$T$103,O10) -> 0 | L9: =I9+K9 -> 0 | M9: =SUMIF($R$6:$R$103,H9,$U$6:$U$103) -> 0 | N9: =H8&"-"&$I$5 -> Northeast-DE | O9: =H8&"-"&$K$5 -> Northeast-PV | P9: =H8&"-"&"TRUE" -> Northeast-TRUE | R9: =IF(ISERROR(VLOOKUP(A9,'Alignment - No Action Needed'!$A$6:$F$1733,5,FALSE)),"",VLOOKUP(A9,'Alignment - No Action Needed'!$A$6:$F$1733,5,FALSE)) -> Mid Atlantic | S9: =LEFT(B9,2) -> DE | T9: =R9&"-"&S9 -> Mid Atlantic-DE | U9: =D9 -> 2500 | V9: =ISNUMBER(SEARCH($V$2,E9)) -> FALSE | W9: =R9&"-"&V9 -> Mid Atlantic-FALSE
A10: 255 | B10: PV-15-00255-1 | C10: Employee Discount Abuse | D10: 85.4875 | E10: Terminated - Released | H10: Southeast | I10: =COUNTIF($T$6:$T$103,N11) -> 2 | J10: =COUNTIF($W$6:$W$103,P11) -> 0 | K10: =COUNTIF($T$6:$T$103,O11) -> 0 | L10: =I10+K10 -> 2 | M10: =SUMIF($R$6:$R$103,H10,$U$6:$U$103) -> 40 | N10: =H9&"-"&$I$5 -> Ohio Valley-DE | O10: =H9&"-"&$K$5 -> Ohio Valley-PV | P10: =H9&"-"&"TRUE" -> Ohio Valley-TRUE | R10: =IF(ISERROR(VLOOKUP(A10,'Alignment - No Action Needed'!$A$6:$F$1733,5,FALSE)),"",VLOOKUP(A10,'Alignment - No Action Needed'!$A$6:$F$1733,5,FALSE)) -> Northeast | S10: =LEFT(B10,2) -> PV | T10: =R10&"-"&S10 -> Northeast-PV | U10: =D10 -> 85.4875 | V10: =ISNUMBER(SEARCH($V$2,E10)) -> FALSE | W10: =R10&"-"&V10 -> Northeast-FALSE
A11: 1083 | B11: DE-15-01083-2 | C11: Merchandise Theft | D11: 20 | E11: Terminated - Released | H11: Southwest | I11: =COUNTIF($T$6:$T$103,N12) -> 0 | J11: =COUNTIF($W$6:$W$103,P12) -> 0 | K11: =COUNTIF($T$6:$T$103,O12) -> 0 | L11: =I11+K11 -> 0 | M11: =SUMIF($R$6:$R$103,H11,$U$6:$U$103) -> 0 | N11: =H10&"-"&$I$5 -> Southeast-DE | O11: =H10&"-"&$K$5 -> Southeast-PV | P11: =H10&"-"&"TRUE" -> Southeast-TRUE | R11: =IF(ISERROR(VLOOKUP(A11,'Alignment - No Action Needed'!$A$6:$F$1733,5,FALSE)),"",VLOOKUP(A11,'Alignment - No Action Needed'!$A$6:$F$1733,5,FALSE)) -> Northeast | S11: =LEFT(B11,2) -> DE | T11: =R11&"-"&S11 -> Northeast-DE | U11: =D11 -> 20 | V11: =ISNUMBER(SEARCH($V$2,E11)) -> FALSE | W11: =R11&"-"&V11 -> Northeast-FALSE
A12: 1083 | B12: DE-15-01083-3 | C12: Unauthorized Markdowns | D12: 0 | E12: Terminated - Released | H12: West | I12: =COUNTIF($T$6:$T$103,N13) -> 2 | J12: =COUNTIF($W$6:$W$103,P13) -> 1 | K12: =COUNTIF($T$6:$T$103,O13) -> 0 | L12: =I12+K12 -> 2 | M12: =SUMIF($R$6:$R$103,H12,$U$6:$U$103) -> 2859.82 | N12: =H11&"-"&$I$5 -> Southwest-DE | O12: =H11&"-"&$K$5 -> Southwest-PV | P12: =H11&"-"&"TRUE" -> Southwest-TRUE | R12: =IF(ISERROR(VLOOKUP(A12,'Alignment - No Action Needed'!$A$6:$F$1733,5,FALSE)),"",VLOOKUP(A12,'Alignment - No Action Needed'!$A$6:$F$1733,5,FALSE)) -> Northeast | S12: =LEFT(B12,2) -> DE | T12: =R12&"-"&S12 -> Northeast-DE | U12: =D12 -> 0 | V12: =ISNUMBER(SEARCH($V$2,E12)) -> FALSE | W12: =R12&"-"&V12 -> Northeast-FALSE
A13: 264 | B13: DE-15-00264-1 | C13: Gift/Merchandise Card Fraud | D13: 0 | E13: Terminated - Released | H13: F&S | I13: =COUNTIF($T$6:$T$103,N14) -> 0 | J13: =COUNTIF($W$6:$W$103,P14) -> 0 | K13: =COUNTIF($T$6:$T$103,O14) -> 0 | L13: =I13+K13 -> 0 | M13: =SUMIF($R$6:$R$103,H13,$U$6:$U$103) -> 0 | N13: =H12&"-"&$I$5 -> West-DE | O13: =H12&"-"&$K$5 -> West-PV | P13: =H12&"-"&"TRUE" -> West-TRUE | R13: =IF(ISERROR(VLOOKUP(A13,'Alignment - No Action Needed'!$A$6:$F$1733,5,FALSE)),"",VLOOKUP(A13,'Alignment - No Action Needed'!$A$6:$F$1733,5,FALSE)) -> Southeast | S13: =LEFT(B13,2) -> DE | T13: =R13&"-"&S13 -> Southeast-DE | U13: =D13 -> 0 | V13: =ISNUMBER(SEARCH($V$2,E13)) -> FALSE | W13: =R13&"-"&V13 -> Southeast-FALSE
A14: 419 | B14: DE-15-00419-3 | C14: Unauthorized Markdowns | D14: 40 | E14: Terminated - Released | H14: Totals | I14: =SUM(I6:I13) -> 8 | J14: =SUM(J6:J13) -> 1 | K14: =SUM(K6:K13) -> 1 | L14: =SUM(L6:L13) -> 9 | M14: =SUM(M6:M13) -> 6595.3075 | N14: =H13&"-"&$I$5 -> F&S-DE | O14: =H13&"-"&$K$5 -> F&S-PV | P14: =H13&"-"&"TRUE" -> F&S-TRUE | R14: =IF(ISERROR(VLOOKUP(A14,'Alignment - No Action Needed'!$A$6:$F$1733,5,FALSE)),"",VLOOKUP(A14,'Alignment - No Action Needed'!$A$6:$F$1733,5,FALSE)) -> Southeast | S14: =LEFT(B14,2) -> DE | T14: =R14&"-"&S14 -> Southeast-DE | U14: =D14 -> 40 | V14: =ISNUMBER(SEARCH($V$2,E14)) -> FALSE | W14: =R14&"-"&V14 -> Southeast-FALSE
N15: =H14&"-"&$I$5 -> Totals-DE | O15: =H14&"-"&$K$5 -> Totals-PV | P15: =H14&"-"&"TRUE" -> Totals-TRUE | R15: =IF(ISERROR(VLOOKUP(A15,'Alignment - No Action Needed'!$A$6:$F$1733,5,FALSE)),"",VLOOKUP(A15,'Alignment - No Action Needed'!$A$6:$F$1733,5,FALSE)) | S15: =LEFT(B15,2) | T15: =R15&"-"&S15 -> - | U15: =D15 -> 0 | V15: =ISNUMBER(SEARCH($V$2,E15)) -> FALSE | W15: =R15&"-"&V15 -> -FALSE
R16: =IF(ISERROR(VLOOKUP(A16,'Alignment - No Action Needed'!$A$6:$F$1733,5,FALSE)),"",VLOOKUP(A16,'Alignment - No Action Needed'!$A$6:$F$1733,5,FALSE)) | S16: =LEFT(B16,2) | T16: =R16&"-"&S16 -> - | U16: =D16 -> 0 | V16: =ISNUMBER(SEARCH($V$2,E16)) -> FALSE | W16: =R16&"-"&V16 -> -FALSE
R17: =IF(ISERROR(VLOOKUP(A17,'Alignment - No Action Needed'!$A$6:$F$1733,5,FALSE)),"",VLOOKUP(A17,'Alignment - No Action Needed'!$A$6:$F$1733,5,FALSE)) | S17: =LEFT(B17,2) | T17: =R17&"-"&S17 -> - | U17: =D17 -> 0 | V17: =ISNUMBER(SEARCH($V$2,E17)) -> FALSE | W17: =R17&"-"&V17 -> -FALSE
R18: =IF(ISERROR(VLOOKUP(A18,'Alignment - No Action Needed'!$A$6:$F$1733,5,FALSE)),"",VLOOKUP(A18,'Alignment - No Action Needed'!$A$6:$F$1733,5,FALSE)) | S18: =LEFT(B18,2) | T18: =R18&"-"&S18 -> - | U18: =D18 -> 0 | V18: =ISNUMBER(SEARCH($V$2,E18)) -> FALSE | W18: =R18&"-"&V18 -> -FALSE
R19: =IF(ISERROR(VLOOKUP(A19,'Alignment - No Action Needed'!$A$6:$F$1733,5,FALSE)),"",VLOOKUP(A19,'Alignment - No Action Needed'!$A$6:$F$1733,5,FALSE)) | S19: =LEFT(B19,2) | T19: =R19&"-"&S19 -> - | U19: =D19 -> 0 | V19: =ISNUMBER(SEARCH($V$2,E19)) -> FALSE | W19: =R19&"-"&V19 -> -FALSE
R20: =IF(ISERROR(VLOOKUP(A20,'Alignment - No Action Needed'!$A$6:$F$1733,5,FALSE)),"",VLOOKUP(A20,'Alignment - No Action Needed'!$A$6:$F$1733,5,FALSE)) | S20: =LEFT(B20,2) | T20: =R20&"-"&S20 -> - | U20: =D20 -> 0 | V20: =ISNUMBER(SEARCH($V$2,E20)) -> FALSE | W20: =R20&"-"&V20 -> -FALSE
R21: =IF(ISERROR(VLOOKUP(A21,'Alignment - No Action Needed'!$A$6:$F$1733,5,FALSE)),"",VLOOKUP(A21,'Alignment - No Action Needed'!$A$6:$F$1733,5,FALSE)) | S21: =LEFT(B21,2) | T21: =R21&"-"&S21 -> - | U21: =D21 -> 0 | V21: =ISNUMBER(SEARCH($V$2,E21)) -> FALSE | W21: =R21&"-"&V21 -> -FALSE
R22: =IF(ISERROR(VLOOKUP(A22,'Alignment - No Action Needed'!$A$6:$F$1733,5,FALSE)),"",VLOOKUP(A22,'Alignment - No Action Needed'!$A$6:$F$1733,5,FALSE)) | S22: =LEFT(B22,2) | T22: =R22&"-"&S22 -> - | U22: =D22 -> 0 | V22: =ISNUMBER(SEARCH($V$2,E22)) -> FALSE | W22: =R22&"-"&V22 -> -FALSE
R23: =IF(ISERROR(VLOOKUP(A23,'Alignment - No Action Needed'!$A$6:$F$1733,5,FALSE)),"",VLOOKUP(A23,'Alignment - No Action Needed'!$A$6:$F$1733,5,FALSE)) | S23: =LEFT(B23,2) | T23: =R23&"-"&S23 -> - | U23: =D23 -> 0 | V23: =ISNUMBER(SEARCH($V$2,E23)) -> FALSE | W23: =R23&"-"&V23 -> -FALSE
R24: =IF(ISERROR(VLOOKUP(A24,'Alignment - No Action Needed'!$A$6:$F$1733,5,FALSE)),"",VLOOKUP(A24,'Alignment - No Action Needed'!$A$6:$F$1733,5,FALSE)) | S24: =LEFT(B24,2) | T24: =R24&"-"&S24 -> - | U24: =D24 -> 0 | V24: =ISNUMBER(SEARCH($V$2,E24)) -> FALSE | W24: =R24&"-"&V24 -> -FALSE
R25: =IF(ISERROR(VLOOKUP(A25,'Alignment - No Action Needed'!$A$6:$F$1733,5,FALSE)),"",VLOOKUP(A25,'Alignment - No Action Needed'!$A$6:$F$1733,5,FALSE)) | S25: =LEFT(B25,2) | T25: =R25&"-"&S25 -> - | U25: =D25 -> 0 | V25: =ISNUMBER(SEARCH($V$2,E25)) -> FALSE | W25: =R25&"-"&V25 -> -FALSE
R26: =IF(ISERROR(VLOOKUP(A26,'Alignment - No Action Needed'!$A$6:$F$1733,5,FALSE)),"",VLOOKUP(A26,'Alignment - No Action Needed'!$A$6:$F$1733,5,FALSE)) | S26: =LEFT(B26,2) | T26: =R26&"-"&S26 -> - | U26: =D26 -> 0 | V26: =ISNUMBER(SEARCH($V$2,E26)) -> FALSE | W26: =R26&"-"&V26 -> -FALSE
R27: =IF(ISERROR(VLOOKUP(A27,'Alignment - No Action Needed'!$A$6:$F$1733,5,FALSE)),"",VLOOKUP(A27,'Alignment - No Action Needed'!$A$6:$F$1733,5,FALSE)) | S27: =LEFT(B27,2) | T27: =R27&"-"&S27 -> - | U27: =D27 -> 0 | V27: =ISNUMBER(SEARCH($V$2,E27)) -> FALSE | W27: =R27&"-"&V27 -> -FALSE
... R103: =IF(ISERROR(VLOOKUP(A103,'Alignment - No Action Needed'!$A$6:$F$1733,5,FALSE)),"",VLOOKUP(A103,'Alignment - No Action Needed'!$A$6:$F$1733,5,FALSE)) | S103: =LEFT(B103,2) | T103: =R103&"-"&S103 -> - | U103: =D103 -> 0 | V103: =ISNUMBER(SEARCH($V$2,E103)) -> FALSE | W103: =R103&"-"&V103 -> -FALSE

Sheet Alignment - No Action Needed
A2: as of 6-24-15
G4: Current | H4: Most Recent | I4: FY15 Goal
A5: Store # | B5: Name | C5: Chain | D5: Zone | E5: Region | F5: District | G5: Shrink Tier | H5: Cost % Actual | I5: Cost % Goal
A6: 5500 | B6: Cranberry | C6: F&S | D6: F&S | E6: F&S | F6: F&S | G6: New | H6: -0.004 | I6: -0.0075
A7: 5501 | B7: Cary | C7: F&S | D7: F&S | E7: F&S | F7: F&S | G7: New | H7: N/A | I7: -0.0075
A8: 5502 | B8: Erie | C8: F&S | D8: F&S | E8: F&S | F8: F&S | G8: New | H8: N/A | I8: -0.0075
A9: 5503 | B9: Crescent Springs | C9: F&S | D9: F&S | E9: F&S | F9: F&S | G9: New | H9: N/A | I9: -0.0075
A10: 5504 | B10: Horseheads | C10: F&S | D10: F&S | E10: F&S | F10: F&S | G10: New | H10: N/A | I10: -0.0075
A11: 5505 | B11: Rochester | C11: F&S | D11: F&S | E11: F&S | F11: F&S | G11: New | H11: N/A | I11: -0.0075
A12: 5506 | B12: Columbus (Easton) | C12: F&S | D12: F&S | E12: F&S | F12: F&S | G12: New | H12: N/A | I12: -0.0075
A13: 5507 | B13: Mobile | C13: F&S | D13: F&S | E13: F&S | F13: F&S | G13: New | H13: N/A | I13: -0.0075
A14: 5508 | B14: Altoona | C14: F&S | D14: F&S | E14: F&S | F14: F&S | G14: New | H14: N/A | I14: -0.0075
A15: 5509 | B15: Washington | C15: F&S | D15: F&S | E15: F&S | F15: F&S | G15: New | H15: N/A | I15: -0.0075
A16: 5510 | B16: Hoover (Birmingham) | C16: F&S | D16: F&S | E16: F&S | F16: F&S | G16: New | H16: N/A | I16: -0.0075
A17: 5511 | B17: Troy (Detroit) | C17: F&S | D17: F&S | E17: F&S | F17: F&S | G17: New | H17: N/A | I17: -0.0075
A18: 5512 | B18: Miamisburg | C18: F&S | D18: F&S | E18: F&S | F18: F&S | G18: New | H18: N/A | I18: -0.0075
A19: 3088 | B19: Columbia | C19: GG | D19: East | E19: Mid Atlantic | F19: Baltimore | G19: G | H19: -0.0038811888 | I19: -0.00395
A20: 3090 | B20: Towson | C20: GG | D20: East | E20: Mid Atlantic | F20: Baltimore | G20: G | H20: -0.00187713 | I20: -0.00345
A21: 798 | B21: Martinsburg | C21: DSG | D21: East | E21: Mid Atlantic | F21: Baltimore | G21: Y | H21: -0.008 | I21: -0.0069
A22: 614 | B22: Frederick | C22: DSG | D22: East | E22: Mid Atlantic | F22: Baltimore | G22: Y | H22: -0.009 | I22: -0.0084
A23: 1206 | B23: Winchester | C23: DSG | D23: East | E23: Mid Atlantic | F23: Baltimore | G23: New | H23: N/A | I23: -0.0086
A24: 77 | B24: Hunt Valley | C24: DSG | D24: East | E24: Mid Atlantic | F24: Baltimore | G24: R | H24: -0.006587928 | I24: -0.0070740742
A25: 78 | B25: Columbia | C25: DSG | D25: East | E25: Mid Atlantic | F25: Baltimore | G25: R | H25: -0.011945149 | I25: -0.011801279
A26: 693 | B26: Westminster | C26: DSG | D26: East | E26: Mid Atlantic | F26: Baltimore | G26: G | H26: -0.0058 | I26: -0.0082
A27: 76 | B27: White Marsh | C27: DSG | D27: East | E27: Mid Atlantic | F27: Baltimore | G27: R | H27: -0.0152 | I27: -0.0094
A28: 79 | B28: Bel Air | C28: DSG | D28: East | E28: Mid Atlantic | F28: Baltimore | G28: Y | H28: -0.0062157499 | I28: -0.0063842806
A29: 107 | B29: Hagerstown | C29: DSG | D29: East | E29: Mid Atlantic | F29: Baltimore | G29: R | H29: -0.0096 | I29: -0.0052
A30: 694 | B30: Glen Burnie | C30: DSG | D30: East | E30: Mid Atlantic | F30: Baltimore | G30: Y | H30: -0.0091022332 | I30: -0.0089541605
A31: 772 | B31: Crofton | C31: DSG | D31: East | E31: Mid Atlantic | F31: Baltimore | G31: Y | H31: -0.010554596 | I31: -0.010212365
A32: 3083 | B32: Rockville | C32: GG | D32: East | E32: Mid Atlantic | F32: District of Columbia | G32: R | H32: -0.007742483 | I32: -0.0065462901
A33: 3089 | B33: Fairfax | C33: GG | D33: East | E33: Mid Atlantic | F33: District of Columbia | G33: R | H33: -0.012096976 | I33: -0.00695
A34: 1141 | B34: Springfield | C34: DSG | D34: East | E34: Mid Atlantic | F34: District of Columbia | G34: R | H34: -0.0136 | I34: -0.0084
A35: 1148 | B35: Culpeper | C35: DSG | D35: East | E35: Mid Atlantic | F35: District of Columbia | G35: New | H35: -0.0074496563 | I35: -0.0074496563
A36: 1173 | B36: Arcola | C36: DSG | D36: East | E36: Mid Atlantic | F36: District of Columbia | G36: New | H36: 0 | I36: -0.0086
A37: 1226 | B37: Leesburg | C37: DSG | D37: East | E37: Mid Atlantic | F37: District of Columbia | G37: New | H37: N/A
A38: 142 | B38: Manassas | C38: DSG | D38: East | E38: Mid Atlantic | F38: District of Columbia | G38: R | H38: -0.0070159478 | I38: -0.0073755418
A39: 413 | B39: Fairfax | C39: DSG | D39: East | E39: Mid Atlantic | F39: District of Columbia | G39: Y | H39: -0.0088 | I39: -0.0086
A40: 414 | B40: Washingtonian | C40: DSG | D40: East | E40: Mid Atlantic | F40: District of Columbia | G40: Y | H40: -0.009 | I40: -0.0109
A41: 641 | B41: Gainesville | C41: DSG | D41: East | E41: Mid Atlantic | F41: District of Columbia | G41: G | H41: -0.0062 | I41: -0.007
A42: 283 | B42: Dulles Town Ctr | C42: DSG | D42: East | E42: Mid Atlantic | F42: District of Columbia | G42: Y | H42: -0.0041034656 | I42: -0.0045065377
...
